2018-12-16 14:46:21,331 INFO: User logged in: leander  [in /Users/Developer/PycharmProjects/microblog/app/routes.py:19]
2018-12-16 14:46:26,798 INFO: User logged in: leander  [in /Users/Developer/PycharmProjects/microblog/app/routes.py:19]
2018-12-16 16:30:42,707 INFO: User logged in: juergen  [in /Users/Developer/PycharmProjects/microblog/app/routes.py:19]
2018-12-16 16:30:55,165 INFO: User logged in: juergen  [in /Users/Developer/PycharmProjects/microblog/app/routes.py:19]
2018-12-16 16:31:02,162 INFO: User logged in: juergen  [in /Users/Developer/PycharmProjects/microblog/app/routes.py:19]
2018-12-16 16:31:08,566 INFO: User logged in: juergen  [in /Users/Developer/PycharmProjects/microblog/app/routes.py:19]
2018-12-16 16:31:21,495 INFO: User logged in: juergen  [in /Users/Developer/PycharmProjects/microblog/app/routes.py:19]
2018-12-16 16:31:22,646 INFO: User logged in: juergen  [in /Users/Developer/PycharmProjects/microblog/app/routes.py:19]
2018-12-16 16:33:22,335 INFO: User logged in: juergen  [in /Users/Developer/PycharmProjects/microblog/app/routes.py:19]
2018-12-16 16:33:28,002 INFO: User logged in: juergen  [in /Users/Developer/PycharmProjects/microblog/app/routes.py:19]
2018-12-18 09:55:34,253 INFO: Microblog startup [in /Users/Developer/PycharmProjects/microblog/app/__init__.py:37]
2018-12-18 09:55:50,073 INFO: User logged in: juergen  [in /Users/Developer/PycharmProjects/microblog/app/routes.py:19]
2018-12-18 09:56:21,931 INFO: User logged in: juergen  [in /Users/Developer/PycharmProjects/microblog/app/routes.py:19]
2018-12-18 12:25:59,800 ERROR: Exception on /index [GET] [in /Users/Developer/PycharmProjects/microblog/venv/lib/python3.7/site-packages/flask/app.py:1761]
Traceback (most recent call last):
  File "/Users/Developer/PycharmProjects/microblog/venv/lib/python3.7/site-packages/sqlalchemy/engine/base.py", line 1193, in _execute_context
    context)
  File "/Users/Developer/PycharmProjects/microblog/venv/lib/python3.7/site-packages/sqlalchemy/engine/default.py", line 509, in do_execute
    cursor.execute(statement, parameters)
psycopg2.OperationalError: server closed the connection unexpectedly
	This probably means the server terminated abnormally
	before or while processing the request.


The above exception was the direct cause of the following exception:

Traceback (most recent call last):
  File "/Users/Developer/PycharmProjects/microblog/venv/lib/python3.7/site-packages/flask/app.py", line 2292, in wsgi_app
    response = self.full_dispatch_request()
  File "/Users/Developer/PycharmProjects/microblog/venv/lib/python3.7/site-packages/flask/app.py", line 1815, in full_dispatch_request
    rv = self.handle_user_exception(e)
  File "/Users/Developer/PycharmProjects/microblog/venv/lib/python3.7/site-packages/flask/app.py", line 1718, in handle_user_exception
    reraise(exc_type, exc_value, tb)
  File "/Users/Developer/PycharmProjects/microblog/venv/lib/python3.7/site-packages/flask/_compat.py", line 35, in reraise
    raise value
  File "/Users/Developer/PycharmProjects/microblog/venv/lib/python3.7/site-packages/flask/app.py", line 1811, in full_dispatch_request
    rv = self.preprocess_request()
  File "/Users/Developer/PycharmProjects/microblog/venv/lib/python3.7/site-packages/flask/app.py", line 2087, in preprocess_request
    rv = func()
  File "/Users/Developer/PycharmProjects/microblog/app/routes.py", line 162, in before_request
    if current_user.is_authenticated:
  File "/Users/Developer/PycharmProjects/microblog/venv/lib/python3.7/site-packages/werkzeug/local.py", line 347, in __getattr__
    return getattr(self._get_current_object(), name)
  File "/Users/Developer/PycharmProjects/microblog/venv/lib/python3.7/site-packages/werkzeug/local.py", line 306, in _get_current_object
    return self.__local()
  File "/Users/Developer/PycharmProjects/microblog/venv/lib/python3.7/site-packages/flask_login/utils.py", line 26, in <lambda>
    current_user = LocalProxy(lambda: _get_user())
  File "/Users/Developer/PycharmProjects/microblog/venv/lib/python3.7/site-packages/flask_login/utils.py", line 335, in _get_user
    current_app.login_manager._load_user()
  File "/Users/Developer/PycharmProjects/microblog/venv/lib/python3.7/site-packages/flask_login/login_manager.py", line 359, in _load_user
    return self.reload_user()
  File "/Users/Developer/PycharmProjects/microblog/venv/lib/python3.7/site-packages/flask_login/login_manager.py", line 321, in reload_user
    user = self.user_callback(user_id)
  File "/Users/Developer/PycharmProjects/microblog/app/models.py", line 81, in load_user
    return User.query.get(int(id))
  File "/Users/Developer/PycharmProjects/microblog/venv/lib/python3.7/site-packages/sqlalchemy/orm/query.py", line 924, in get
    ident, loading.load_on_pk_identity)
  File "/Users/Developer/PycharmProjects/microblog/venv/lib/python3.7/site-packages/sqlalchemy/orm/query.py", line 1007, in _get_impl
    return db_load_fn(self, primary_key_identity)
  File "/Users/Developer/PycharmProjects/microblog/venv/lib/python3.7/site-packages/sqlalchemy/orm/loading.py", line 250, in load_on_pk_identity
    return q.one()
  File "/Users/Developer/PycharmProjects/microblog/venv/lib/python3.7/site-packages/sqlalchemy/orm/query.py", line 2954, in one
    ret = self.one_or_none()
  File "/Users/Developer/PycharmProjects/microblog/venv/lib/python3.7/site-packages/sqlalchemy/orm/query.py", line 2924, in one_or_none
    ret = list(self)
  File "/Users/Developer/PycharmProjects/microblog/venv/lib/python3.7/site-packages/sqlalchemy/orm/query.py", line 2995, in __iter__
    return self._execute_and_instances(context)
  File "/Users/Developer/PycharmProjects/microblog/venv/lib/python3.7/site-packages/sqlalchemy/orm/query.py", line 3018, in _execute_and_instances
    result = conn.execute(querycontext.statement, self._params)
  File "/Users/Developer/PycharmProjects/microblog/venv/lib/python3.7/site-packages/sqlalchemy/engine/base.py", line 948, in execute
    return meth(self, multiparams, params)
  File "/Users/Developer/PycharmProjects/microblog/venv/lib/python3.7/site-packages/sqlalchemy/sql/elements.py", line 269, in _execute_on_connection
    return connection._execute_clauseelement(self, multiparams, params)
  File "/Users/Developer/PycharmProjects/microblog/venv/lib/python3.7/site-packages/sqlalchemy/engine/base.py", line 1060, in _execute_clauseelement
    compiled_sql, distilled_params
  File "/Users/Developer/PycharmProjects/microblog/venv/lib/python3.7/site-packages/sqlalchemy/engine/base.py", line 1200, in _execute_context
    context)
  File "/Users/Developer/PycharmProjects/microblog/venv/lib/python3.7/site-packages/sqlalchemy/engine/base.py", line 1413, in _handle_dbapi_exception
    exc_info
  File "/Users/Developer/PycharmProjects/microblog/venv/lib/python3.7/site-packages/sqlalchemy/util/compat.py", line 265, in raise_from_cause
    reraise(type(exception), exception, tb=exc_tb, cause=cause)
  File "/Users/Developer/PycharmProjects/microblog/venv/lib/python3.7/site-packages/sqlalchemy/util/compat.py", line 248, in reraise
    raise value.with_traceback(tb)
  File "/Users/Developer/PycharmProjects/microblog/venv/lib/python3.7/site-packages/sqlalchemy/engine/base.py", line 1193, in _execute_context
    context)
  File "/Users/Developer/PycharmProjects/microblog/venv/lib/python3.7/site-packages/sqlalchemy/engine/default.py", line 509, in do_execute
    cursor.execute(statement, parameters)
sqlalchemy.exc.OperationalError: (psycopg2.OperationalError) server closed the connection unexpectedly
	This probably means the server terminated abnormally
	before or while processing the request.
 [SQL: 'SELECT "user".id AS user_id, "user".username AS user_username, "user".email AS user_email, "user".password_hash AS user_password_hash, "user".about_me AS user_about_me, "user".last_seen AS user_last_seen \nFROM "user" \nWHERE "user".id = %(param_1)s'] [parameters: {'param_1': 1}] (Background on this error at: http://sqlalche.me/e/e3q8)
2018-12-18 12:26:03,246 INFO: User logged in: juergen  [in /Users/Developer/PycharmProjects/microblog/app/routes.py:19]
2018-12-18 13:23:55,662 INFO: Microblog startup [in /Users/Developer/PycharmProjects/microblog/app/__init__.py:40]
2018-12-18 13:24:11,541 INFO: User logged in: juergen  [in /Users/Developer/PycharmProjects/microblog/app/routes.py:19]
2018-12-18 13:24:16,374 INFO: User logged in: juergen  [in /Users/Developer/PycharmProjects/microblog/app/routes.py:19]
2018-12-18 13:24:32,517 INFO: User logged in: juergen  [in /Users/Developer/PycharmProjects/microblog/app/routes.py:19]
2018-12-18 13:24:34,638 INFO: User logged in: juergen  [in /Users/Developer/PycharmProjects/microblog/app/routes.py:19]
2018-12-18 13:24:36,252 INFO: User logged in: juergen  [in /Users/Developer/PycharmProjects/microblog/app/routes.py:19]
2018-12-18 14:10:07,825 INFO: Microblog startup [in /Users/Developer/PycharmProjects/microblog/app/__init__.py:44]
