2018-12-25 19:24:38,582 ERROR: Exception on /auth/login [GET] [in /Users/Developer/PycharmProjects/microblog/venv/lib/python3.7/site-packages/flask/app.py:1761]
Traceback (most recent call last):
  File "/Users/Developer/PycharmProjects/microblog/venv/lib/python3.7/site-packages/flask/app.py", line 2292, in wsgi_app
    response = self.full_dispatch_request()
  File "/Users/Developer/PycharmProjects/microblog/venv/lib/python3.7/site-packages/flask/app.py", line 1815, in full_dispatch_request
    rv = self.handle_user_exception(e)
  File "/Users/Developer/PycharmProjects/microblog/venv/lib/python3.7/site-packages/flask/app.py", line 1718, in handle_user_exception
    reraise(exc_type, exc_value, tb)
  File "/Users/Developer/PycharmProjects/microblog/venv/lib/python3.7/site-packages/flask/_compat.py", line 35, in reraise
    raise value
  File "/Users/Developer/PycharmProjects/microblog/venv/lib/python3.7/site-packages/flask/app.py", line 1813, in full_dispatch_request
    rv = self.dispatch_request()
  File "/Users/Developer/PycharmProjects/microblog/venv/lib/python3.7/site-packages/flask/app.py", line 1799, in dispatch_request
    return self.view_functions[rule.endpoint](**req.view_args)
  File "/Users/Developer/PycharmProjects/microblog/app/auth/routes.py", line 28, in login
    return render_template('auth/login.html', title=_('Sign In'), form=form)
NameError: name '_' is not defined
2018-12-25 19:24:38,965 ERROR: Exception on /favicon.ico [GET] [in /Users/Developer/PycharmProjects/microblog/venv/lib/python3.7/site-packages/flask/app.py:1761]
Traceback (most recent call last):
  File "/Users/Developer/PycharmProjects/microblog/venv/lib/python3.7/site-packages/flask/app.py", line 1813, in full_dispatch_request
    rv = self.dispatch_request()
  File "/Users/Developer/PycharmProjects/microblog/venv/lib/python3.7/site-packages/flask/app.py", line 1791, in dispatch_request
    self.raise_routing_exception(req)
  File "/Users/Developer/PycharmProjects/microblog/venv/lib/python3.7/site-packages/flask/app.py", line 1774, in raise_routing_exception
    raise request.routing_exception
  File "/Users/Developer/PycharmProjects/microblog/venv/lib/python3.7/site-packages/flask/ctx.py", line 336, in match_request
    self.url_adapter.match(return_rule=True)
  File "/Users/Developer/PycharmProjects/microblog/venv/lib/python3.7/site-packages/werkzeug/routing.py", line 1581, in match
    raise NotFound()
werkzeug.exceptions.NotFound: 404 Not Found: The requested URL was not found on the server.  If you entered the URL manually please check your spelling and try again.

During handling of the above exception, another exception occurred:

Traceback (most recent call last):
  File "/Users/Developer/PycharmProjects/microblog/venv/lib/python3.7/site-packages/flask/app.py", line 2292, in wsgi_app
    response = self.full_dispatch_request()
  File "/Users/Developer/PycharmProjects/microblog/venv/lib/python3.7/site-packages/flask/app.py", line 1815, in full_dispatch_request
    rv = self.handle_user_exception(e)
  File "/Users/Developer/PycharmProjects/microblog/venv/lib/python3.7/site-packages/flask/app.py", line 1713, in handle_user_exception
    return self.handle_http_exception(e)
  File "/Users/Developer/PycharmProjects/microblog/venv/lib/python3.7/site-packages/flask/app.py", line 1644, in handle_http_exception
    return handler(e)
  File "/Users/Developer/PycharmProjects/microblog/app/errors/handlers.py", line 7, in not_found_error
    return render_template('errors/404.html'),404
  File "/Users/Developer/PycharmProjects/microblog/venv/lib/python3.7/site-packages/flask/templating.py", line 134, in render_template
    return _render(ctx.app.jinja_env.get_or_select_template(template_name_or_list),
  File "/Users/Developer/PycharmProjects/microblog/venv/lib/python3.7/site-packages/jinja2/environment.py", line 869, in get_or_select_template
    return self.get_template(template_name_or_list, parent, globals)
  File "/Users/Developer/PycharmProjects/microblog/venv/lib/python3.7/site-packages/jinja2/environment.py", line 830, in get_template
    return self._load_template(name, self.make_globals(globals))
  File "/Users/Developer/PycharmProjects/microblog/venv/lib/python3.7/site-packages/jinja2/environment.py", line 804, in _load_template
    template = self.loader.load(self, name, globals)
  File "/Users/Developer/PycharmProjects/microblog/venv/lib/python3.7/site-packages/jinja2/loaders.py", line 125, in load
    code = environment.compile(source, name, filename)
  File "/Users/Developer/PycharmProjects/microblog/venv/lib/python3.7/site-packages/jinja2/environment.py", line 591, in compile
    self.handle_exception(exc_info, source_hint=source_hint)
  File "/Users/Developer/PycharmProjects/microblog/venv/lib/python3.7/site-packages/jinja2/environment.py", line 780, in handle_exception
    reraise(exc_type, exc_value, tb)
  File "/Users/Developer/PycharmProjects/microblog/venv/lib/python3.7/site-packages/jinja2/_compat.py", line 37, in reraise
    raise value.with_traceback(tb)
  File "/Users/Developer/PycharmProjects/microblog/app/templates/errors/404.html", line 4, in template
    <h1>{{ File not found }}</h1>
  File "/Users/Developer/PycharmProjects/microblog/venv/lib/python3.7/site-packages/jinja2/environment.py", line 497, in _parse
    return Parser(self, source, name, encode_filename(filename)).parse()
  File "/Users/Developer/PycharmProjects/microblog/venv/lib/python3.7/site-packages/jinja2/parser.py", line 901, in parse
    result = nodes.Template(self.subparse(), lineno=1)
  File "/Users/Developer/PycharmProjects/microblog/venv/lib/python3.7/site-packages/jinja2/parser.py", line 883, in subparse
    rv = self.parse_statement()
  File "/Users/Developer/PycharmProjects/microblog/venv/lib/python3.7/site-packages/jinja2/parser.py", line 130, in parse_statement
    return getattr(self, 'parse_' + self.stream.current.value)()
  File "/Users/Developer/PycharmProjects/microblog/venv/lib/python3.7/site-packages/jinja2/parser.py", line 268, in parse_block
    node.body = self.parse_statements(('name:endblock',), drop_needle=True)
  File "/Users/Developer/PycharmProjects/microblog/venv/lib/python3.7/site-packages/jinja2/parser.py", line 165, in parse_statements
    result = self.subparse(end_tokens)
  File "/Users/Developer/PycharmProjects/microblog/venv/lib/python3.7/site-packages/jinja2/parser.py", line 876, in subparse
    self.stream.expect('variable_end')
  File "/Users/Developer/PycharmProjects/microblog/venv/lib/python3.7/site-packages/jinja2/lexer.py", line 384, in expect
    self.name, self.filename)
jinja2.exceptions.TemplateSyntaxError: expected token 'end of print statement', got 'not'
2018-12-25 19:29:19,496 INFO: Microblog startup [in /Users/Developer/PycharmProjects/microblog/app/__init__.py:74]
2018-12-25 19:29:28,204 ERROR: Exception on /auth/login [GET] [in /Users/Developer/PycharmProjects/microblog/venv/lib/python3.7/site-packages/flask/app.py:1761]
Traceback (most recent call last):
  File "/Users/Developer/PycharmProjects/microblog/venv/lib/python3.7/site-packages/flask/app.py", line 2292, in wsgi_app
    response = self.full_dispatch_request()
  File "/Users/Developer/PycharmProjects/microblog/venv/lib/python3.7/site-packages/flask/app.py", line 1815, in full_dispatch_request
    rv = self.handle_user_exception(e)
  File "/Users/Developer/PycharmProjects/microblog/venv/lib/python3.7/site-packages/flask/app.py", line 1718, in handle_user_exception
    reraise(exc_type, exc_value, tb)
  File "/Users/Developer/PycharmProjects/microblog/venv/lib/python3.7/site-packages/flask/_compat.py", line 35, in reraise
    raise value
  File "/Users/Developer/PycharmProjects/microblog/venv/lib/python3.7/site-packages/flask/app.py", line 1813, in full_dispatch_request
    rv = self.dispatch_request()
  File "/Users/Developer/PycharmProjects/microblog/venv/lib/python3.7/site-packages/flask/app.py", line 1799, in dispatch_request
    return self.view_functions[rule.endpoint](**req.view_args)
  File "/Users/Developer/PycharmProjects/microblog/app/auth/routes.py", line 28, in login
    return render_template('auth/login.html', title=_('Sign In'), form=form)
NameError: name '_' is not defined
2018-12-25 19:29:32,373 ERROR: Exception on /auth/login [GET] [in /Users/Developer/PycharmProjects/microblog/venv/lib/python3.7/site-packages/flask/app.py:1761]
Traceback (most recent call last):
  File "/Users/Developer/PycharmProjects/microblog/venv/lib/python3.7/site-packages/flask/app.py", line 2292, in wsgi_app
    response = self.full_dispatch_request()
  File "/Users/Developer/PycharmProjects/microblog/venv/lib/python3.7/site-packages/flask/app.py", line 1815, in full_dispatch_request
    rv = self.handle_user_exception(e)
  File "/Users/Developer/PycharmProjects/microblog/venv/lib/python3.7/site-packages/flask/app.py", line 1718, in handle_user_exception
    reraise(exc_type, exc_value, tb)
  File "/Users/Developer/PycharmProjects/microblog/venv/lib/python3.7/site-packages/flask/_compat.py", line 35, in reraise
    raise value
  File "/Users/Developer/PycharmProjects/microblog/venv/lib/python3.7/site-packages/flask/app.py", line 1813, in full_dispatch_request
    rv = self.dispatch_request()
  File "/Users/Developer/PycharmProjects/microblog/venv/lib/python3.7/site-packages/flask/app.py", line 1799, in dispatch_request
    return self.view_functions[rule.endpoint](**req.view_args)
  File "/Users/Developer/PycharmProjects/microblog/app/auth/routes.py", line 28, in login
    return render_template('auth/login.html', title=_('Sign In'), form=form)
NameError: name '_' is not defined
2018-12-25 19:31:27,715 INFO: Microblog startup [in /Users/Developer/PycharmProjects/microblog/app/__init__.py:74]
